Traceback (most recent call last):
  File "run_sir.py", line 31, in <module>
    **config['args'])
  File "/home/gcgibson/covid/covid/util.py", line 234, in run_place
    num_samples=num_samples)
  File "/home/gcgibson/covid/covid/models/base.py", line 76, in infer
    mcmc.run(rng_key, **self.obs, **args)    
  File "/home/gcgibson/anaconda3/lib/python3.7/site-packages/numpyro/infer/mcmc.py", line 1214, in run
    args, kwargs, collect_fields)
  File "/home/gcgibson/anaconda3/lib/python3.7/site-packages/numpyro/infer/mcmc.py", line 1087, in _single_chain_mcmc
    model_args=args, model_kwargs=kwargs)
  File "/home/gcgibson/anaconda3/lib/python3.7/site-packages/numpyro/infer/mcmc.py", line 523, in init
    model_kwargs=model_kwargs)
  File "/home/gcgibson/anaconda3/lib/python3.7/site-packages/numpyro/infer/util.py", line 372, in find_valid_initial_params
    init_params, is_valid = _find_valid_params(rng_key)
  File "/home/gcgibson/anaconda3/lib/python3.7/site-packages/numpyro/infer/util.py", line 361, in _find_valid_params
    _, _, prototype_params, is_valid = init_state = body_fn((0, rng_key_, None, None))
  File "/home/gcgibson/anaconda3/lib/python3.7/site-packages/numpyro/infer/util.py", line 331, in body_fn
    model_trace = trace(seeded_model).get_trace(*model_args, **model_kwargs)
  File "/home/gcgibson/anaconda3/lib/python3.7/site-packages/numpyro/handlers.py", line 149, in get_trace
    self(*args, **kwargs)
  File "/home/gcgibson/anaconda3/lib/python3.7/site-packages/numpyro/primitives.py", line 65, in __call__
    return self.fn(*args, **kwargs)
  File "/home/gcgibson/anaconda3/lib/python3.7/site-packages/numpyro/primitives.py", line 65, in __call__
    return self.fn(*args, **kwargs)
  File "/home/gcgibson/covid/covid/models/SEIRD_incident.py", line 65, in __call__
    sys.exit()
NameError: name 'sys' is not defined
